Workbook

Sheet Instrucciones
B1: Registro El Tilichero: fichas, consultas y resumen
B2: Plantilla vacía. Sirve para saber qué video trae pedidos sin guardar datos personales.
B5: Leyenda
B6: Celda amarilla | C6: Se llena a mano.
B7: Celda gris | C7: Se calcula sola. No escribir encima.
B8: Fila roja en «Consultas» | C8: Algo no cuadra en esa fila (ver «Control del registro» en «Resumen»).
B10: Cuándo llenar
B11: Antes de grabar | C11: Hoja «Fichas»: una fila por producto (GAME, RETRO, RGB). Ningún dato entra a un guion hasta que su columna «¿Verificado?» diga Sí.
B12: Cada día | C12: Hoja «Consultas»: una fila por conversación nueva de WhatsApp. El N.º se pone solo al escribir la fecha o el código.
B13: A los 7 días | C13: Hoja «Resumen»: escribí Desde/Hasta, la inversión en pauta de cada código (vacía = sin pauta), el alcance de cada pieza por plataforma (de Insights), las fechas de publicación y el alcance de GAME1 y GAME2 en su ventana, y contestá las preguntas de condiciones. Mandá el resumen a Altiora.
B15: Códigos de pieza
B16: GAME1 y GAME2 | C16: Dos videos distintos del MISMO audífono gaming (se comparan entre sí).
B17: RETRO1 | C17: Video de la consola portátil retro.
B18: RGB1 | C18: Video del mouse o periférico gaming (o del accesorio que lo sustituya).
B19: Regla común | C19: El código dice de qué pieza viene la consulta; el canal dice dónde la vio.
B20: OTRO | C20: Vino por una publicación sin código que sí se identifica: Marketplace, grupo, estado de WhatsApp, clip o anuncio con foto. Se anota con su canal.
B21: SIN CODIGO | C21: No se sabe la pieza: no dijo código ni de qué publicación viene, aunque diga el canal («lo vi en Instagram») o que se lo recomendaron. También si escribió un código que no está en la lista (copialo en la nota). Se anota con su canal: Instagram, Facebook (página), TikTok, Recomendación o No dijo.
B23: Canal de origen
B24: Regla | C24: El canal es dónde vio la publicación por primera vez, no por dónde escribe. Casi todo termina en WhatsApp, pero eso no cambia el canal.
B25: Instagram / TikTok | C25: Vio una publicación, reel, historia o clip sin pagar en esa red.
B26: Facebook (página) | C26: Vio una publicación o reel de la página de El Tilichero, sin pagar.
B27: Facebook Marketplace | C27: Vio la publicación en Marketplace, aunque escriba por Messenger y después pase a WhatsApp. Código: OTRO.
B28: Grupo de Facebook | C28: Vio la publicación en un grupo de compra y venta. Código: OTRO.
B29: Estado de WhatsApp | C29: Vio un estado de WhatsApp del negocio. Código: OTRO.
B30: Anuncio pagado (Meta) | C30: Llegó por un anuncio pagado de Facebook o Instagram, por ejemplo uno de clic a WhatsApp. Código: el de la pieza si el anuncio la usa; si no, OTRO.
B31: Recomendación / Otro / No dijo | C31: Recomendación: se lo recomendó alguien (código SIN CODIGO). Otro: cualquier otro origen. No dijo: no sabe o no contesta (código SIN CODIGO; no insistir).
B33: Alcance (Insights)
B34: Qué anotar | C34: El total de cuentas o personas alcanzadas por cada pieza en cada plataforma, no las reproducciones. Solo el número: nunca nombres de cuentas ni listas de quién la vio.
B35: Dónde verlo | C35: En las estadísticas (Insights) de cada publicación, con cuenta profesional. Instagram: «Cuentas alcanzadas». Facebook (Meta Business Suite): «Alcance». TikTok: el dato de espectadores del video. Los nombres pueden cambiar con la app.
B36: Cuándo leerlo | C36: Cuadro general: el día «Hasta». Prueba A: el día «Cuenta hasta» de cada pieza. El alcance se acumula, así que leerlo otro día cambia el número.
B38: No registrar
B39: Nunca | C39: Nombres, teléfonos, direcciones exactas, correos, capturas de chats ni datos de pago. La zona es solo GAM / Fuera de GAM / No dijo.
B41: Definiciones
B42: Consulta repetida | C42: La misma persona vuelve a escribir por lo mismo: marcá Sí y actualizá la fila original. Las repetidas no se cuentan.
B43: Consulta cualificada | C43: La persona dice qué producto o necesidad tiene Y en qué zona recibe.
B44: Cotizada | C44: Le mandaste precio final con envío.
B45: Pedido confirmado | C45: La persona confirmó que lo compra. Todavía no es plata.
B46: Cobrado | C46: El pago entró. Solo aquí se anota el monto en colones.
B47: Venta neta | C47: Cobrado menos devoluciones y descuentos. No se calcula en este archivo: si hubo devolución, escribí DEVOLUCIÓN y el monto en la nota, sin borrar el cobro.
B49: Cómo leer
...

Sheet Fichas
A1: Código | B1: Producto | C1: Estado de la ficha | D1: Campos listos (de 16) | E1: 1. Marca | I1: 2. Modelo exacto | M1: 3. Foto o video propio disponible | Q1: 4. Precio vigente (₡) | U1: 5. Costo unitario (₡) · CONFIDENCIAL | Y1: 6. Stock (unidades) | AC1: 7. Compatibilidad comprobada (con qué y cómo) | AG1: 8. Características comprobadas (conexión, iluminación, botones…) | AK1: 9. Garantía: plazo | AO1: 10. Garantía: quién la da | AS1: 11. Entrega: zonas | AW1: 12. Entrega: costo (₡) | BA1: 13. Entrega: plazo | BE1: 14. Origen / autenticidad | BI1: 15. Contenido incluido y permisos de gameplay o música (RETRO) | BM1: 16. Quién aprueba los claims
E2: Valor | F2: Fuente / cómo se comprobó | G2: Fecha | H2: ¿Verificado? | I2: Valor | J2: Fuente / cómo se comprobó | K2: Fecha | L2: ¿Verificado? | M2: Valor | N2: Fuente / cómo se comprobó | O2: Fecha | P2: ¿Verificado? | Q2: Valor | R2: Fuente / cómo se comprobó | S2: Fecha | T2: ¿Verificado? | U2: Valor | V2: Fuente / cómo se comprobó | W2: Fecha | X2: ¿Verificado? | Y2: Valor | Z2: Fuente / cómo se comprobó | AA2: Fecha | AB2: ¿Verificado? | AC2: Valor | AD2: Fuente / cómo se comprobó | AE2: Fecha | AF2: ¿Verificado? | AG2: Valor | AH2: Fuente / cómo se comprobó | AI2: Fecha | AJ2: ¿Verificado? | AK2: Valor | AL2: Fuente / cómo se comprobó | AM2: Fecha | AN2: ¿Verificado? | AO2: Valor | AP2: Fuente / cómo se comprobó | AQ2: Fecha | AR2: ¿Verificado? | AS2: Valor | AT2: Fuente / cómo se comprobó | AU2: Fecha | AV2: ¿Verificado? | AW2: Valor | AX2: Fuente / cómo se comprobó | AY2: Fecha | AZ2: ¿Verificado? | BA2: Valor | BB2: Fuente / cómo se comprobó | BC2: Fecha | BD2: ¿Verificado? | BE2: Valor | BF2: Fuente / cómo se comprobó | BG2: Fecha | BH2: ¿Verificado? | BI2: Valor | BJ2: Fuente / cómo se comprobó | BK2: Fecha | BL2: ¿Verificado? | BM2: Valor | BN2: Fuente / cómo se comprobó | BO2: Fecha | BP2: ¿Verificado?
A3: GAME | B3: Audífonos gaming (mismo SKU para GAME1 y GAME2) | C3: =IF(D3=16,"COMPLETA","INCOMPLETA: faltan "&(16-D3)&" campos") -> INCOMPLETA: faltan 16 campos | D3: =SUMPRODUCT((MOD(COLUMN(E3:BP3)-COLUMN($E$3),4)=3)*((E3:BP3="Sí")+(E3:BP3="No aplica"))) -> 0
A4: RETRO | B4: Consola portátil retro (RETRO1) | C4: =IF(D4=16,"COMPLETA","INCOMPLETA: faltan "&(16-D4)&" campos") -> INCOMPLETA: faltan 16 campos | D4: =SUMPRODUCT((MOD(COLUMN(E4:BP4)-COLUMN($E$4),4)=3)*((E4:BP4="Sí")+(E4:BP4="No aplica"))) -> 0
A5: RGB | B5: Mouse o periférico gaming, o accesorio sustituto validado (RGB1) | C5: =IF(D5=16,"COMPLETA","INCOMPLETA: faltan "&(16-D5)&" campos") -> INCOMPLETA: faltan 16 campos | D5: =SUMPRODUCT((MOD(COLUMN(E5:BP5)-COLUMN($E$5),4)=3)*((E5:BP5="Sí")+(E5:BP5="No aplica"))) -> 0
A7: Regla: ningún claim entra a un guion hasta que su campo diga ¿Verificado? = Sí. GAME1 y GAME2 usan la misma fila GAME. El costo unitario es confidencial.

Sheet Consultas
A1: N.º de consulta | B1: Fecha | C1: Canal de origen (dónde nos vio) | D1: Código de pieza | E1: Producto consultado | F1: Zona | G1: ¿Consulta repetida? | H1: Cualificada | I1: Cotizada | J1: Pedido confirmado | K1: Cobrado | L1: Monto cobrado (₡) | M1: Minutos hasta la primera respuesta | N1: Objeción principal | O1: Nota breve (sin datos personales)
A2: =IF(AND(B2="",D2=""),"",ROW()-1)
A3: =IF(AND(B3="",D3=""),"",ROW()-1)
A4: =IF(AND(B4="",D4=""),"",ROW()-1)
A5: =IF(AND(B5="",D5=""),"",ROW()-1)
A6: =IF(AND(B6="",D6=""),"",ROW()-1)
A7: =IF(AND(B7="",D7=""),"",ROW()-1)
A8: =IF(AND(B8="",D8=""),"",ROW()-1)
A9: =IF(AND(B9="",D9=""),"",ROW()-1)
A10: =IF(AND(B10="",D10=""),"",ROW()-1)
A11: =IF(AND(B11="",D11=""),"",ROW()-1)
A12: =IF(AND(B12="",D12=""),"",ROW()-1)
A13: =IF(AND(B13="",D13=""),"",ROW()-1)
... A301: =IF(AND(B301="",D301=""),"",ROW()-1)

Sheet Resumen
A1: Resumen de la prueba · El Tilichero
A2: Cuenta solo consultas únicas (¿Consulta repetida? distinto de Sí) con fecha dentro del periodo. Amarillo = llenar a mano; gris = se calcula solo.
A4: Desde | C4: Vacía = desde el inicio del registro.
A5: Hasta | C5: Vacía = hasta el final del registro. La pauta de abajo debe ser la de ESTAS mismas fechas.
A6: Estado del registro | B6: =IF(SUM(I98:I105)=0,"Sin inconsistencias detectadas en «Consultas».","Hay "&SUM(I98:I105)&" inconsistencias: revisá las filas en rojo de «Consultas» y el control al final de esta hoja.") -> Sin inconsistencias detectadas en «Consultas».
A8: Embudo por código de pieza
A9: Código | B9: Consultas únicas | C9: Cualificadas | D9: Cotizaciones | E9: Pedidos confirmados | F9: Cobrados | G9: Ingresos cobrados (₡) | H9: Inversión en pauta (₡) · escribir a mano | I9: Cualificadas / consultas | J9: Pedidos / cualificadas | K9: Costo por consulta cualificada (₡) | L9: Cualificadas / alcance
A10: GAME1 | B10: =COUNTIFS(Consultas!$D$2:$D$1000,$A10,Consultas!$G$2:$G$1000,"<>Sí",Consultas!$B$2:$B$1000,">="&IF($B$4="",1,$B$4),Consultas!$B$2:$B$1000,"<="&IF($B$5="",2958465,$B$5)) -> 0 | C10: =COUNTIFS(Consultas!$D$2:$D$1000,$A10,Consultas!$G$2:$G$1000,"<>Sí",Consultas!$B$2:$B$1000,">="&IF($B$4="",1,$B$4),Consultas!$B$2:$B$1000,"<="&IF($B$5="",2958465,$B$5),Consultas!$H$2:$H$1000,"Sí") -> 0 | D10: =COUNTIFS(Consultas!$D$2:$D$1000,$A10,Consultas!$G$2:$G$1000,"<>Sí",Consultas!$B$2:$B$1000,">="&IF($B$4="",1,$B$4),Consultas!$B$2:$B$1000,"<="&IF($B$5="",2958465,$B$5),Consultas!$I$2:$I$1000,"Sí") -> 0 | E10: =COUNTIFS(Consultas!$D$2:$D$1000,$A10,Consultas!$G$2:$G$1000,"<>Sí",Consultas!$B$2:$B$1000,">="&IF($B$4="",1,$B$4),Consultas!$B$2:$B$1000,"<="&IF($B$5="",2958465,$B$5),Consultas!$J$2:$J$1000,"Sí") -> 0 | F10: =COUNTIFS(Consultas!$D$2:$D$1000,$A10,Consultas!$G$2:$G$1000,"<>Sí",Consultas!$B$2:$B$1000,">="&IF($B$4="",1,$B$4),Consultas!$B$2:$B$1000,"<="&IF($B$5="",2958465,$B$5),Consultas!$K$2:$K$1000,"Sí") -> 0 | G10: =SUMIFS(Consultas!$L$2:$L$1000,Consultas!$D$2:$D$1000,$A10,Consultas!$G$2:$G$1000,"<>Sí",Consultas!$B$2:$B$1000,">="&IF($B$4="",1,$B$4),Consultas!$B$2:$B$1000,"<="&IF($B$5="",2958465,$B$5),Consultas!$K$2:$K$1000,"Sí") -> 0 | I10: =IF(B10=0,"NO CALCULABLE",C10/B10) -> NO CALCULABLE | J10: =IF(C10=0,"NO CALCULABLE",E10/C10) -> NO CALCULABLE | K10: =IF(C10=0,"NO CALCULABLE",IF(N(H10)<=0,"SIN PAUTA",H10/C10)) -> NO CALCULABLE | L10: =IF(N($E$26)=0,"NO CALCULABLE",C10/$E$26) -> NO CALCULABLE
A11: GAME2 | B11: =COUNTIFS(Consultas!$D$2:$D$1000,$A11,Consultas!$G$2:$G$1000,"<>Sí",Consultas!$B$2:$B$1000,">="&IF($B$4="",1,$B$4),Consultas!$B$2:$B$1000,"<="&IF($B$5="",2958465,$B$5)) -> 0 | C11: =COUNTIFS(Consultas!$D$2:$D$1000,$A11,Consultas!$G$2:$G$1000,"<>Sí",Consultas!$B$2:$B$1000,">="&IF($B$4="",1,$B$4),Consultas!$B$2:$B$1000,"<="&IF($B$5="",2958465,$B$5),Consultas!$H$2:$H$1000,"Sí") -> 0 | D11: =COUNTIFS(Consultas!$D$2:$D$1000,$A11,Consultas!$G$2:$G$1000,"<>Sí",Consultas!$B$2:$B$1000,">="&IF($B$4="",1,$B$4),Consultas!$B$2:$B$1000,"<="&IF($B$5="",2958465,$B$5),Consultas!$I$2:$I$1000,"Sí") -> 0 | E11: =COUNTIFS(Consultas!$D$2:$D$1000,$A11,Consultas!$G$2:$G$1000,"<>Sí",Consultas!$B$2:$B$1000,">="&IF($B$4="",1,$B$4),Consultas!$B$2:$B$1000,"<="&IF($B$5="",2958465,$B$5),Consultas!$J$2:$J$1000,"Sí") -> 0 | F11: =COUNTIFS(Consultas!$D$2:$D$1000,$A11,Consultas!$G$2:$G$1000,"<>Sí",Consultas!$B$2:$B$1000,">="&IF($B$4="",1,$B$4),Consultas!$B$2:$B$1000,"<="&IF($B$5="",2958465,$B$5),Consultas!$K$2:$K$1000,"Sí") -> 0 | G11: =SUMIFS(Consultas!$L$2:$L$1000,Consultas!$D$2:$D$1000,$A11,Consultas!$G$2:$G$1000,"<>Sí",Consultas!$B$2:$B$1000,">="&IF($B$4="",1,$B$4),Consultas!$B$2:$B$1000,"<="&IF($B$5="",2958465,$B$5),Consultas!$K$2:$K$1000,"Sí") -> 0 | I11: =IF(B11=0,"NO CALCULABLE",C11/B11) -> NO CALCULABLE | J11: =IF(C11=0,"NO CALCULABLE",E11/C11) -> NO CALCULABLE | K11: =IF(C11=0,"NO CALCULABLE",IF(N(H11)<=0,"SIN PAUTA",H11/C11)) -> NO CALCULABLE | L11: =IF(N($E$27)=0,"NO CALCULABLE",C11/$E$27) -> NO CALCULABLE
A12: RETRO1 | B12: =COUNTIFS(Consultas!$D$2:$D$1000,$A12,Consultas!$G$2:$G$1000,"<>Sí",Consultas!$B$2:$B$1000,">="&IF($B$4="",1,$B$4),Consultas!$B$2:$B$1000,"<="&IF($B$5="",2958465,$B$5)) -> 0 | C12: =COUNTIFS(Consultas!$D$2:$D$1000,$A12,Consultas!$G$2:$G$1000,"<>Sí",Consultas!$B$2:$B$1000,">="&IF($B$4="",1,$B$4),Consultas!$B$2:$B$1000,"<="&IF($B$5="",2958465,$B$5),Consultas!$H$2:$H$1000,"Sí") -> 0 | D12: =COUNTIFS(Consultas!$D$2:$D$1000,$A12,Consultas!$G$2:$G$1000,"<>Sí",Consultas!$B$2:$B$1000,">="&IF($B$4="",1,$B$4),Consultas!$B$2:$B$1000,"<="&IF($B$5="",2958465,$B$5),Consultas!$I$2:$I$1000,"Sí") -> 0 | E12: =COUNTIFS(Consultas!$D$2:$D$1000,$A12,Consultas!$G$2:$G$1000,"<>Sí",Consultas!$B$2:$B$1000,">="&IF($B$4="",1,$B$4),Consultas!$B$2:$B$1000,"<="&IF($B$5="",2958465,$B$5),Consultas!$J$2:$J$1000,"Sí") -> 0 | F12: =COUNTIFS(Consultas!$D$2:$D$1000,$A12,Consultas!$G$2:$G$1000,"<>Sí",Consultas!$B$2:$B$1000,">="&IF($B$4="",1,$B$4),Consultas!$B$2:$B$1000,"<="&IF($B$5="",2958465,$B$5),Consultas!$K$2:$K$1000,"Sí") -> 0 | G12: =SUMIFS(Consultas!$L$2:$L$1000,Consultas!$D$2:$D$1000,$A12,Consultas!$G$2:$G$1000,"<>Sí",Consultas!$B$2:$B$1000,">="&IF($B$4="",1,$B$4),Consultas!$B$2:$B$1000,"<="&IF($B$5="",2958465,$B$5),Consultas!$K$2:$K$1000,"Sí") -> 0 | I12: =IF(B12=0,"NO CALCULABLE",C12/B12) -> NO CALCULABLE | J12: =IF(C12=0,"NO CALCULABLE",E12/C12) -> NO CALCULABLE | K12: =IF(C12=0,"NO CALCULABLE",IF(N(H12)<=0,"SIN PAUTA",H12/C12)) -> NO CALCULABLE | L12: =IF(N($E$28)=0,"NO CALCULABLE",C12/$E$28) -> NO CALCULABLE
A13: RGB1 | B13: =COUNTIFS(Consultas!$D$2:$D$1000,$A13,Consultas!$G$2:$G$1000,"<>Sí",Consultas!$B$2:$B$1000,">="&IF($B$4="",1,$B$4),Consultas!$B$2:$B$1000,"<="&IF($B$5="",2958465,$B$5)) -> 0 | C13: =COUNTIFS(Consultas!$D$2:$D$1000,$A13,Consultas!$G$2:$G$1000,"<>Sí",Consultas!$B$2:$B$1000,">="&IF($B$4="",1,$B$4),Consultas!$B$2:$B$1000,"<="&IF($B$5="",2958465,$B$5),Consultas!$H$2:$H$1000,"Sí") -> 0 | D13: =COUNTIFS(Consultas!$D$2:$D$1000,$A13,Consultas!$G$2:$G$1000,"<>Sí",Consultas!$B$2:$B$1000,">="&IF($B$4="",1,$B$4),Consultas!$B$2:$B$1000,"<="&IF($B$5="",2958465,$B$5),Consultas!$I$2:$I$1000,"Sí") -> 0 | E13: =COUNTIFS(Consultas!$D$2:$D$1000,$A13,Consultas!$G$2:$G$1000,"<>Sí",Consultas!$B$2:$B$1000,">="&IF($B$4="",1,$B$4),Consultas!$B$2:$B$1000,"<="&IF($B$5="",2958465,$B$5),Consultas!$J$2:$J$1000,"Sí") -> 0 | F13: =COUNTIFS(Consultas!$D$2:$D$1000,$A13,Consultas!$G$2:$G$1000,"<>Sí",Consultas!$B$2:$B$1000,">="&IF($B$4="",1,$B$4),Consultas!$B$2:$B$1000,"<="&IF($B$5="",2958465,$B$5),Consultas!$K$2:$K$1000,"Sí") -> 0 | G13: =SUMIFS(Consultas!$L$2:$L$1000,Consultas!$D$2:$D$1000,$A13,Consultas!$G$2:$G$1000,"<>Sí",Consultas!$B$2:$B$1000,">="&IF($B$4="",1,$B$4),Consultas!$B$2:$B$1000,"<="&IF($B$5="",2958465,$B$5),Consultas!$K$2:$K$1000,"Sí") -> 0 | I13: =IF(B13=0,"NO CALCULABLE",C13/B13) -> NO CALCULABLE | J13: =IF(C13=0,"NO CALCULABLE",E13/C13) -> NO CALCULABLE | K13: =IF(C13=0,"NO CALCULABLE",IF(N(H13)<=0,"SIN PAUTA",H13/C13)) -> NO CALCULABLE | L13: =IF(N($E$29)=0,"NO CALCULABLE",C13/$E$29) -> NO CALCULABLE
A14: OTRO | B14: =COUNTIFS(Consultas!$D$2:$D$1000,$A14,Consultas!$G$2:$G$1000,"<>Sí",Consultas!$B$2:$B$1000,">="&IF($B$4="",1,$B$4),Consultas!$B$2:$B$1000,"<="&IF($B$5="",2958465,$B$5)) -> 0 | C14: =COUNTIFS(Consultas!$D$2:$D$1000,$A14,Consultas!$G$2:$G$1000,"<>Sí",Consultas!$B$2:$B$1000,">="&IF($B$4="",1,$B$4),Consultas!$B$2:$B$1000,"<="&IF($B$5="",2958465,$B$5),Consultas!$H$2:$H$1000,"Sí") -> 0 | D14: =COUNTIFS(Consultas!$D$2:$D$1000,$A14,Consultas!$G$2:$G$1000,"<>Sí",Consultas!$B$2:$B$1000,">="&IF($B$4="",1,$B$4),Consultas!$B$2:$B$1000,"<="&IF($B$5="",2958465,$B$5),Consultas!$I$2:$I$1000,"Sí") -> 0 | E14: =COUNTIFS(Consultas!$D$2:$D$1000,$A14,Consultas!$G$2:$G$1000,"<>Sí",Consultas!$B$2:$B$1000,">="&IF($B$4="",1,$B$4),Consultas!$B$2:$B$1000,"<="&IF($B$5="",2958465,$B$5),Consultas!$J$2:$J$1000,"Sí") -> 0 | F14: =COUNTIFS(Consultas!$D$2:$D$1000,$A14,Consultas!$G$2:$G$1000,"<>Sí",Consultas!$B$2:$B$1000,">="&IF($B$4="",1,$B$4),Consultas!$B$2:$B$1000,"<="&IF($B$5="",2958465,$B$5),Consultas!$K$2:$K$1000,"Sí") -> 0 | G14: =SUMIFS(Consultas!$L$2:$L$1000,Consultas!$D$2:$D$1000,$A14,Consultas!$G$2:$G$1000,"<>Sí",Consultas!$B$2:$B$1000,">="&IF($B$4="",1,$B$4),Consultas!$B$2:$B$1000,"<="&IF($B$5="",2958465,$B$5),Consultas!$K$2:$K$1000,"Sí") -> 0 | H14: No aplica | I14: =IF(B14=0,"NO CALCULABLE",C14/B14) -> NO CALCULABLE | J14: =IF(C14=0,"NO CALCULABLE",E14/C14) -> NO CALCULABLE | K14: =IF(C14=0,"NO CALCULABLE",IF(N(H14)<=0,"SIN PAUTA",H14/C14)) -> NO CALCULABLE | L14: No aplica
A15: SIN CODIGO | B15: =COUNTIFS(Consultas!$D$2:$D$1000,$A15,Consultas!$G$2:$G$1000,"<>Sí",Consultas!$B$2:$B$1000,">="&IF($B$4="",1,$B$4),Consultas!$B$2:$B$1000,"<="&IF($B$5="",2958465,$B$5)) -> 0 | C15: =COUNTIFS(Consultas!$D$2:$D$1000,$A15,Consultas!$G$2:$G$1000,"<>Sí",Consultas!$B$2:$B$1000,">="&IF($B$4="",1,$B$4),Consultas!$B$2:$B$1000,"<="&IF($B$5="",2958465,$B$5),Consultas!$H$2:$H$1000,"Sí") -> 0 | D15: =COUNTIFS(Consultas!$D$2:$D$1000,$A15,Consultas!$G$2:$G$1000,"<>Sí",Consultas!$B$2:$B$1000,">="&IF($B$4="",1,$B$4),Consultas!$B$2:$B$1000,"<="&IF($B$5="",2958465,$B$5),Consultas!$I$2:$I$1000,"Sí") -> 0 | E15: =COUNTIFS(Consultas!$D$2:$D$1000,$A15,Consultas!$G$2:$G$1000,"<>Sí",Consultas!$B$2:$B$1000,">="&IF($B$4="",1,$B$4),Consultas!$B$2:$B$1000,"<="&IF($B$5="",2958465,$B$5),Consultas!$J$2:$J$1000,"Sí") -> 0 | F15: =COUNTIFS(Consultas!$D$2:$D$1000,$A15,Consultas!$G$2:$G$1000,"<>Sí",Consultas!$B$2:$B$1000,">="&IF($B$4="",1,$B$4),Consultas!$B$2:$B$1000,"<="&IF($B$5="",2958465,$B$5),Consultas!$K$2:$K$1000,"Sí") -> 0 | G15: =SUMIFS(Consultas!$L$2:$L$1000,Consultas!$D$2:$D$1000,$A15,Consultas!$G$2:$G$1000,"<>Sí",Consultas!$B$2:$B$1000,">="&IF($B$4="",1,$B$4),Consultas!$B$2:$B$1000,"<="&IF($B$5="",2958465,$B$5),Consultas!$K$2:$K$1000,"Sí") -> 0 | H15: No aplica | I15: =IF(B15=0,"NO CALCULABLE",C15/B15) -> NO CALCULABLE | J15: =IF(C15=0,"NO CALCULABLE",E15/C15) -> NO CALCULABLE | K15: =IF(C15=0,"NO CALCULABLE",IF(N(H15)<=0,"SIN PAUTA",H15/C15)) -> NO CALCULABLE | L15: No aplica
A16: Total | B16: =SUM(B10:B15) -> 0 | C16: =SUM(C10:C15) -> 0 | D16: =SUM(D10:D15) -> 0 | E16: =SUM(E10:E15) -> 0 | F16: =SUM(F10:F15) -> 0 | G16: =SUM(G10:G15) -> 0 | H16: =IF(SUMIF($H$10:$H$13,">0")=0,"SIN PAUTA",SUMIF($H$10:$H$13,">0")) -> SIN PAUTA | I16: =IF(B16=0,"NO CALCULABLE",C16/B16) -> NO CALCULABLE | J16: =IF(C16=0,"NO CALCULABLE",E16/C16) -> NO CALCULABLE | K16: =IF(C16=0,"NO CALCULABLE",IF(SUMIF($H$10:$H$13,">0")=0,"SIN PAUTA",IF(SUMIF($H$10:$H$13,">0",$C$10:$C$13)=0,"NO CALCULABLE",SUMIF($H$10:$H$13,">0")/SUMIF($H$10:$H$13,">0",$C$10:$C$13)))) -> NO CALCULABLE | L16: =IF(SUMIF($E$26:$E$29,">0")=0,"NO CALCULABLE",SUMIF($E$26:$E$29,">0",$C$10:$C$13)/SUMIF($E$26:$E$29,">0")) -> NO CALCULABLE
A17: NO CALCULABLE = el denominador es 0 o está vacío; no significa 0 %. SIN PAUTA = no hay inversión escrita.
A18: Ingresos cobrados no es venta neta: faltan devoluciones, descuentos, costo del producto y envío.
A19: Las piezas salen en días distintos: este cuadro suma, no compara piezas. GAME1 frente a GAME2 se mira en el bloque «Prueba A».
A20: Cualificadas / alcance usa el bloque de alcance de abajo (mismo periodo Desde/Hasta). Sin alcance: NO CALCULABLE, y se miran los volúmenes absolutos.
A22: Alcance por pieza y plataforma (de Insights, escribir a mano)
A23: Tiene que ser del MISMO periodo que Desde/Hasta: leé el alcance el día «Hasta». Anotá cuentas o personas alcanzadas, no reproducciones.
A24: Solo números totales, sin datos de personas. Dejá vacía la plataforma donde la pieza no se publicó. La suma puede contar dos veces a quien vio la pieza en dos plataformas.
A25: Pieza | B25: Instagram | C25: Facebook | D25: TikTok | E25: Total | F25: Leído el (fecha)
A26: GAME1 | E26: =IF(COUNT(B26:D26)=0,"SIN DATO",SUM(B26:D26)) -> SIN DATO
A27: GAME2 | E27: =IF(COUNT(B27:D27)=0,"SIN DATO",SUM(B27:D27)) -> SIN DATO
A28: RETRO1 | E28: =IF(COUNT(B28:D28)=0,"SIN DATO",SUM(B28:D28)) -> SIN DATO
A29: RGB1 | E29: =IF(COUNT(B29:D29)=0,"SIN DATO",SUM(B29:D29)) -> SIN DATO
A31: Embudo por canal de origen
A32: Mismo filtro Desde/Hasta y misma regla de repetidas que el embudo por código. Cuenta las consultas con código de pieza (OTRO y SIN CODIGO incluidos).
A33: La pauta de este cuadro y la del embudo por código NO se suman: es el mismo gasto visto de dos formas. Anotala en un solo lugar:
A34: si el anuncio usa una pieza con código (GAME1, GAME2, RETRO1, RGB1), en el embudo por código; si no tiene código (por ejemplo, un anuncio con foto), aquí en «Anuncio pagado (Meta)».
A35: Canal de origen | B35: Consultas únicas | C35: Cualificadas | D35: Cotizaciones | E35: Pedidos confirmados | F35: Cobrados | G35: Ingresos cobrados (₡) | H35: Inversión en pauta (₡) · escribir a mano | I35: Cualificadas / consultas | J35: Pedidos / cualificadas | K35: Costo por consulta cualificada (₡)
A36: Instagram | B36: =COUNTIFS(Consultas!$C$2:$C$1000,$A36,Consultas!$D$2:$D$1000,"<>",Consultas!$G$2:$G$1000,"<>Sí",Consultas!$B$2:$B$1000,">="&IF($B$4="",1,$B$4),Consultas!$B$2:$B$1000,"<="&IF($B$5="",2958465,$B$5)) -> 0 | C36: =COUNTIFS(Consultas!$C$2:$C$1000,$A36,Consultas!$D$2:$D$1000,"<>",Consultas!$G$2:$G$1000,"<>Sí",Consultas!$B$2:$B$1000,">="&IF($B$4="",1,$B$4),Consultas!$B$2:$B$1000,"<="&IF($B$5="",2958465,$B$5),Consultas!$H$2:$H$1000,"Sí") -> 0 | D36: =COUNTIFS(Consultas!$C$2:$C$1000,$A36,Consultas!$D$2:$D$1000,"<>",Consultas!$G$2:$G$1000,"<>Sí",Consultas!$B$2:$B$1000,">="&IF($B$4="",1,$B$4),Consultas!$B$2:$B$1000,"<="&IF($B$5="",2958465,$B$5),Consultas!$I$2:$I$1000,"Sí") -> 0 | E36: =COUNTIFS(Consultas!$C$2:$C$1000,$A36,Consultas!$D$2:$D$1000,"<>",Consultas!$G$2:$G$1000,"<>Sí",Consultas!$B$2:$B$1000,">="&IF($B$4="",1,$B$4),Consultas!$B$2:$B$1000,"<="&IF($B$5="",2958465,$B$5),Consultas!$J$2:$J$1000,"Sí") -> 0 | F36: =COUNTIFS(Consultas!$C$2:$C$1000,$A36,Consultas!$D$2:$D$1000,"<>",Consultas!$G$2:$G$1000,"<>Sí",Consultas!$B$2:$B$1000,">="&IF($B$4="",1,$B$4),Consultas!$B$2:$B$1000,"<="&IF($B$5="",2958465,$B$5),Consultas!$K$2:$K$1000,"Sí") -> 0 | G36: =SUMIFS(Consultas!$L$2:$L$1000,Consultas!$C$2:$C$1000,$A36,Consultas!$D$2:$D$1000,"<>",Consultas!$G$2:$G$1000,"<>Sí",Consultas!$B$2:$B$1000,">="&IF($B$4="",1,$B$4),Consultas!$B$2:$B$1000,"<="&IF($B$5="",2958465,$B$5),Consultas!$K$2:$K$1000,"Sí") -> 0 | H36: No aplica | I36: =IF(B36=0,"NO CALCULABLE",C36/B36) -> NO CALCULABLE | J36: =IF(C36=0,"NO CALCULABLE",E36/C36) -> NO CALCULABLE | K36: No aplica
A37: Facebook (página) | B37: =COUNTIFS(Consultas!$C$2:$C$1000,$A37,Consultas!$D$2:$D$1000,"<>",Consultas!$G$2:$G$1000,"<>Sí",Consultas!$B$2:$B$1000,">="&IF($B$4="",1,$B$4),Consultas!$B$2:$B$1000,"<="&IF($B$5="",2958465,$B$5)) -> 0 | C37: =COUNTIFS(Consultas!$C$2:$C$1000,$A37,Consultas!$D$2:$D$1000,"<>",Consultas!$G$2:$G$1000,"<>Sí",Consultas!$B$2:$B$1000,">="&IF($B$4="",1,$B$4),Consultas!$B$2:$B$1000,"<="&IF($B$5="",2958465,$B$5),Consultas!$H$2:$H$1000,"Sí") -> 0 | D37: =COUNTIFS(Consultas!$C$2:$C$1000,$A37,Consultas!$D$2:$D$1000,"<>",Consultas!$G$2:$G$1000,"<>Sí",Consultas!$B$2:$B$1000,">="&IF($B$4="",1,$B$4),Consultas!$B$2:$B$1000,"<="&IF($B$5="",2958465,$B$5),Consultas!$I$2:$I$1000,"Sí") -> 0 | E37: =COUNTIFS(Consultas!$C$2:$C$1000,$A37,Consultas!$D$2:$D$1000,"<>",Consultas!$G$2:$G$1000,"<>Sí",Consultas!$B$2:$B$1000,">="&IF($B$4="",1,$B$4),Consultas!$B$2:$B$1000,"<="&IF($B$5="",2958465,$B$5),Consultas!$J$2:$J$1000,"Sí") -> 0 | F37: =COUNTIFS(Consultas!$C$2:$C$1000,$A37,Consultas!$D$2:$D$1000,"<>",Consultas!$G$2:$G$1000,"<>Sí",Consultas!$B$2:$B$1000,">="&IF($B$4="",1,$B$4),Consultas!$B$2:$B$1000,"<="&IF($B$5="",2958465,$B$5),Consultas!$K$2:$K$1000,"Sí") -> 0 | G37: =SUMIFS(Consultas!$L$2:$L$1000,Consultas!$C$2:$C$1000,$A37,Consultas!$D$2:$D$1000,"<>",Consultas!$G$2:$G$1000,"<>Sí",Consultas!$B$2:$B$1000,">="&IF($B$4="",1,$B$4),Consultas!$B$2:$B$1000,"<="&IF($B$5="",2958465,$B$5),Consultas!$K$2:$K$1000,"Sí") -> 0 | H37: No aplica | I37: =IF(B37=0,"NO CALCULABLE",C37/B37) -> NO CALCULABLE | J37: =IF(C37=0,"NO CALCULABLE",E37/C37) -> NO CALCULABLE | K37: No aplica
A38: Facebook Marketplace | B38: =COUNTIFS(Consultas!$C$2:$C$1000,$A38,Consultas!$D$2:$D$1000,"<>",Consultas!$G$2:$G$1000,"<>Sí",Consultas!$B$2:$B$1000,">="&IF($B$4="",1,$B$4),Consultas!$B$2:$B$1000,"<="&IF($B$5="",2958465,$B$5)) -> 0 | C38: =COUNTIFS(Consultas!$C$2:$C$1000,$A38,Consultas!$D$2:$D$1000,"<>",Consultas!$G$2:$G$1000,"<>Sí",Consultas!$B$2:$B$1000,">="&IF($B$4="",1,$B$4),Consultas!$B$2:$B$1000,"<="&IF($B$5="",2958465,$B$5),Consultas!$H$2:$H$1000,"Sí") -> 0 | D38: =COUNTIFS(Consultas!$C$2:$C$1000,$A38,Consultas!$D$2:$D$1000,"<>",Consultas!$G$2:$G$1000,"<>Sí",Consultas!$B$2:$B$1000,">="&IF($B$4="",1,$B$4),Consultas!$B$2:$B$1000,"<="&IF($B$5="",2958465,$B$5),Consultas!$I$2:$I$1000,"Sí") -> 0 | E38: =COUNTIFS(Consultas!$C$2:$C$1000,$A38,Consultas!$D$2:$D$1000,"<>",Consultas!$G$2:$G$1000,"<>Sí",Consultas!$B$2:$B$1000,">="&IF($B$4="",1,$B$4),Consultas!$B$2:$B$1000,"<="&IF($B$5="",2958465,$B$5),Consultas!$J$2:$J$1000,"Sí") -> 0 | F38: =COUNTIFS(Consultas!$C$2:$C$1000,$A38,Consultas!$D$2:$D$1000,"<>",Consultas!$G$2:$G$1000,"<>Sí",Consultas!$B$2:$B$1000,">="&IF($B$4="",1,$B$4),Consultas!$B$2:$B$1000,"<="&IF($B$5="",2958465,$B$5),Consultas!$K$2:$K$1000,"Sí") -> 0 | G38: =SUMIFS(Consultas!$L$2:$L$1000,Consultas!$C$2:$C$1000,$A38,Consultas!$D$2:$D$1000,"<>",Consultas!$G$2:$G$1000,"<>Sí",Consultas!$B$2:$B$1000,">="&IF($B$4="",1,$B$4),Consultas!$B$2:$B$1000,"<="&IF($B$5="",2958465,$B$5),Consultas!$K$2:$K$1000,"Sí") -> 0 | H38: No aplica | I38: =IF(B38=0,"NO CALCULABLE",C38/B38) -> NO CALCULABLE | J38: =IF(C38=0,"NO CALCULABLE",E38/C38) -> NO CALCULABLE | K38: No aplica
A39: Grupo de Facebook | B39: =COUNTIFS(Consultas!$C$2:$C$1000,$A39,Consultas!$D$2:$D$1000,"<>",Consultas!$G$2:$G$1000,"<>Sí",Consultas!$B$2:$B$1000,">="&IF($B$4="",1,$B$4),Consultas!$B$2:$B$1000,"<="&IF($B$5="",2958465,$B$5)) -> 0 | C39: =COUNTIFS(Consultas!$C$2:$C$1000,$A39,Consultas!$D$2:$D$1000,"<>",Consultas!$G$2:$G$1000,"<>Sí",Consultas!$B$2:$B$1000,">="&IF($B$4="",1,$B$4),Consultas!$B$2:$B$1000,"<="&IF($B$5="",2958465,$B$5),Consultas!$H$2:$H$1000,"Sí") -> 0 | D39: =COUNTIFS(Consultas!$C$2:$C$1000,$A39,Consultas!$D$2:$D$1000,"<>",Consultas!$G$2:$G$1000,"<>Sí",Consultas!$B$2:$B$1000,">="&IF($B$4="",1,$B$4),Consultas!$B$2:$B$1000,"<="&IF($B$5="",2958465,$B$5),Consultas!$I$2:$I$1000,"Sí") -> 0 | E39: =COUNTIFS(Consultas!$C$2:$C$1000,$A39,Consultas!$D$2:$D$1000,"<>",Consultas!$G$2:$G$1000,"<>Sí",Consultas!$B$2:$B$1000,">="&IF($B$4="",1,$B$4),Consultas!$B$2:$B$1000,"<="&IF($B$5="",2958465,$B$5),Consultas!$J$2:$J$1000,"Sí") -> 0 | F39: =COUNTIFS(Consultas!$C$2:$C$1000,$A39,Consultas!$D$2:$D$1000,"<>",Consultas!$G$2:$G$1000,"<>Sí",Consultas!$B$2:$B$1000,">="&IF($B$4="",1,$B$4),Consultas!$B$2:$B$1000,"<="&IF($B$5="",2958465,$B$5),Consultas!$K$2:$K$1000,"Sí") -> 0 | G39: =SUMIFS(Consultas!$L$2:$L$1000,Consultas!$C$2:$C$1000,$A39,Consultas!$D$2:$D$1000,"<>",Consultas!$G$2:$G$1000,"<>Sí",Consultas!$B$2:$B$1000,">="&IF($B$4="",1,$B$4),Consultas!$B$2:$B$1000,"<="&IF($B$5="",2958465,$B$5),Consultas!$K$2:$K$1000,"Sí") -> 0 | H39: No aplica | I39: =IF(B39=0,"NO CALCULABLE",C39/B39) -> NO CALCULABLE | J39: =IF(C39=0,"NO CALCULABLE",E39/C39) -> NO CALCULABLE | K39: No aplica
A40: TikTok | B40: =COUNTIFS(Consultas!$C$2:$C$1000,$A40,Consultas!$D$2:$D$1000,"<>",Consultas!$G$2:$G$1000,"<>Sí",Consultas!$B$2:$B$1000,">="&IF($B$4="",1,$B$4),Consultas!$B$2:$B$1000,"<="&IF($B$5="",2958465,$B$5)) -> 0 | C40: =COUNTIFS(Consultas!$C$2:$C$1000,$A40,Consultas!$D$2:$D$1000,"<>",Consultas!$G$2:$G$1000,"<>Sí",Consultas!$B$2:$B$1000,">="&IF($B$4="",1,$B$4),Consultas!$B$2:$B$1000,"<="&IF($B$5="",2958465,$B$5),Consultas!$H$2:$H$1000,"Sí") -> 0 | D40: =COUNTIFS(Consultas!$C$2:$C$1000,$A40,Consultas!$D$2:$D$1000,"<>",Consultas!$G$2:$G$1000,"<>Sí",Consultas!$B$2:$B$1000,">="&IF($B$4="",1,$B$4),Consultas!$B$2:$B$1000,"<="&IF($B$5="",2958465,$B$5),Consultas!$I$2:$I$1000,"Sí") -> 0 | E40: =COUNTIFS(Consultas!$C$2:$C$1000,$A40,Consultas!$D$2:$D$1000,"<>",Consultas!$G$2:$G$1000,"<>Sí",Consultas!$B$2:$B$1000,">="&IF($B$4="",1,$B$4),Consultas!$B$2:$B$1000,"<="&IF($B$5="",2958465,$B$5),Consultas!$J$2:$J$1000,"Sí") -> 0 | F40: =COUNTIFS(Consultas!$C$2:$C$1000,$A40,Consultas!$D$2:$D$1000,"<>",Consultas!$G$2:$G$1000,"<>Sí",Consultas!$B$2:$B$1000,">="&IF($B$4="",1,$B$4),Consultas!$B$2:$B$1000,"<="&IF($B$5="",2958465,$B$5),Consultas!$K$2:$K$1000,"Sí") -> 0 | G40: =SUMIFS(Consultas!$L$2:$L$1000,Consultas!$C$2:$C$1000,$A40,Consultas!$D$2:$D$1000,"<>",Consultas!$G$2:$G$1000,"<>Sí",Consultas!$B$2:$B$1000,">="&IF($B$4="",1,$B$4),Consultas!$B$2:$B$1000,"<="&IF($B$5="",2958465,$B$5),Consultas!$K$2:$K$1000,"Sí") -> 0 | H40: No aplica | I40: =IF(B40=0,"NO CALCULABLE",C40/B40) -> NO CALCULABLE | J40: =IF(C40=0,"NO CALCULABLE",E40/C40) -> NO CALCULABLE | K40: No aplica
A41: Estado de WhatsApp | B41: =COUNTIFS(Consultas!$C$2:$C$1000,$A41,Consultas!$D$2:$D$1000,"<>",Consultas!$G$2:$G$1000,"<>Sí",Consultas!$B$2:$B$1000,">="&IF($B$4="",1,$B$4),Consultas!$B$2:$B$1000,"<="&IF($B$5="",2958465,$B$5)) -> 0 | C41: =COUNTIFS(Consultas!$C$2:$C$1000,$A41,Consultas!$D$2:$D$1000,"<>",Consultas!$G$2:$G$1000,"<>Sí",Consultas!$B$2:$B$1000,">="&IF($B$4="",1,$B$4),Consultas!$B$2:$B$1000,"<="&IF($B$5="",2958465,$B$5),Consultas!$H$2:$H$1000,"Sí") -> 0 | D41: =COUNTIFS(Consultas!$C$2:$C$1000,$A41,Consultas!$D$2:$D$1000,"<>",Consultas!$G$2:$G$1000,"<>Sí",Consultas!$B$2:$B$1000,">="&IF($B$4="",1,$B$4),Consultas!$B$2:$B$1000,"<="&IF($B$5="",2958465,$B$5),Consultas!$I$2:$I$1000,"Sí") -> 0 | E41: =COUNTIFS(Consultas!$C$2:$C$1000,$A41,Consultas!$D$2:$D$1000,"<>",Consultas!$G$2:$G$1000,"<>Sí",Consultas!$B$2:$B$1000,">="&IF($B$4="",1,$B$4),Consultas!$B$2:$B$1000,"<="&IF($B$5="",2958465,$B$5),Consultas!$J$2:$J$1000,"Sí") -> 0 | F41: =COUNTIFS(Consultas!$C$2:$C$1000,$A41,Consultas!$D$2:$D$1000,"<>",Consultas!$G$2:$G$1000,"<>Sí",Consultas!$B$2:$B$1000,">="&IF($B$4="",1,$B$4),Consultas!$B$2:$B$1000,"<="&IF($B$5="",2958465,$B$5),Consultas!$K$2:$K$1000,"Sí") -> 0 | G41: =SUMIFS(Consultas!$L$2:$L$1000,Consultas!$C$2:$C$1000,$A41,Consultas!$D$2:$D$1000,"<>",Consultas!$G$2:$G$1000,"<>Sí",Consultas!$B$2:$B$1000,">="&IF($B$4="",1,$B$4),Consultas!$B$2:$B$1000,"<="&IF($B$5="",2958465,$B$5),Consultas!$K$2:$K$1000,"Sí") -> 0 | H41: No aplica | I41: =IF(B41=0,"NO CALCULABLE",C41/B41) -> NO CALCULABLE | J41: =IF(C41=0,"NO CALCULABLE",E41/C41) -> NO CALCULABLE | K41: No aplica
A42: Anuncio pagado (Meta) | B42: =COUNTIFS(Consultas!$C$2:$C$1000,$A42,Consultas!$D$2:$D$1000,"<>",Consultas!$G$2:$G$1000,"<>Sí",Consultas!$B$2:$B$1000,">="&IF($B$4="",1,$B$4),Consultas!$B$2:$B$1000,"<="&IF($B$5="",2958465,$B$5)) -> 0 | C42: =COUNTIFS(Consultas!$C$2:$C$1000,$A42,Consultas!$D$2:$D$1000,"<>",Consultas!$G$2:$G$1000,"<>Sí",Consultas!$B$2:$B$1000,">="&IF($B$4="",1,$B$4),Consultas!$B$2:$B$1000,"<="&IF($B$5="",2958465,$B$5),Consultas!$H$2:$H$1000,"Sí") -> 0 | D42: =COUNTIFS(Consultas!$C$2:$C$1000,$A42,Consultas!$D$2:$D$1000,"<>",Consultas!$G$2:$G$1000,"<>Sí",Consultas!$B$2:$B$1000,">="&IF($B$4="",1,$B$4),Consultas!$B$2:$B$1000,"<="&IF($B$5="",2958465,$B$5),Consultas!$I$2:$I$1000,"Sí") -> 0 | E42: =COUNTIFS(Consultas!$C$2:$C$1000,$A42,Consultas!$D$2:$D$1000,"<>",Consultas!$G$2:$G$1000,"<>Sí",Consultas!$B$2:$B$1000,">="&IF($B$4="",1,$B$4),Consultas!$B$2:$B$1000,"<="&IF($B$5="",2958465,$B$5),Consultas!$J$2:$J$1000,"Sí") -> 0 | F42: =COUNTIFS(Consultas!$C$2:$C$1000,$A42,Consultas!$D$2:$D$1000,"<>",Consultas!$G$2:$G$1000,"<>Sí",Consultas!$B$2:$B$1000,">="&IF($B$4="",1,$B$4),Consultas!$B$2:$B$1000,"<="&IF($B$5="",2958465,$B$5),Consultas!$K$2:$K$1000,"Sí") -> 0 | G42: =SUMIFS(Consultas!$L$2:$L$1000,Consultas!$C$2:$C$1000,$A42,Consultas!$D$2:$D$1000,"<>",Consultas!$G$2:$G$1000,"<>Sí",Consultas!$B$2:$B$1000,">="&IF($B$4="",1,$B$4),Consultas!$B$2:$B$1000,"<="&IF($B$5="",2958465,$B$5),Consultas!$K$2:$K$1000,"Sí") -> 0 | I42: =IF(B42=0,"NO CALCULABLE",C42/B42) -> NO CALCULABLE | J42: =IF(C42=0,"NO CALCULABLE",E42/C42) -> NO CALCULABLE | K42: =IF(C42=0,"NO CALCULABLE",IF(N(H42)<=0,"SIN PAUTA",H42/C42)) -> NO CALCULABLE
A43: Recomendación | B43: =COUNTIFS(Consultas!$C$2:$C$1000,$A43,Consultas!$D$2:$D$1000,"<>",Consultas!$G$2:$G$1000,"<>Sí",Consultas!$B$2:$B$1000,">="&IF($B$4="",1,$B$4),Consultas!$B$2:$B$1000,"<="&IF($B$5="",2958465,$B$5)) -> 0 | C43: =COUNTIFS(Consultas!$C$2:$C$1000,$A43,Consultas!$D$2:$D$1000,"<>",Consultas!$G$2:$G$1000,"<>Sí",Consultas!$B$2:$B$1000,">="&IF($B$4="",1,$B$4),Consultas!$B$2:$B$1000,"<="&IF($B$5="",2958465,$B$5),Consultas!$H$2:$H$1000,"Sí") -> 0 | D43: =COUNTIFS(Consultas!$C$2:$C$1000,$A43,Consultas!$D$2:$D$1000,"<>",Consultas!$G$2:$G$1000,"<>Sí",Consultas!$B$2:$B$1000,">="&IF($B$4="",1,$B$4),Consultas!$B$2:$B$1000,"<="&IF($B$5="",2958465,$B$5),Consultas!$I$2:$I$1000,"Sí") -> 0 | E43: =COUNTIFS(Consultas!$C$2:$C$1000,$A43,Consultas!$D$2:$D$1000,"<>",Consultas!$G$2:$G$1000,"<>Sí",Consultas!$B$2:$B$1000,">="&IF($B$4="",1,$B$4),Consultas!$B$2:$B$1000,"<="&IF($B$5="",2958465,$B$5),Consultas!$J$2:$J$1000,"Sí") -> 0 | F43: =COUNTIFS(Consultas!$C$2:$C$1000,$A43,Consultas!$D$2:$D$1000,"<>",Consultas!$G$2:$G$1000,"<>Sí",Consultas!$B$2:$B$1000,">="&IF($B$4="",1,$B$4),Consultas!$B$2:$B$1000,"<="&IF($B$5="",2958465,$B$5),Consultas!$K$2:$K$1000,"Sí") -> 0 | G43: =SUMIFS(Consultas!$L$2:$L$1000,Consultas!$C$2:$C$1000,$A43,Consultas!$D$2:$D$1000,"<>",Consultas!$G$2:$G$1000,"<>Sí",Consultas!$B$2:$B$1000,">="&IF($B$4="",1,$B$4),Consultas!$B$2:$B$1000,"<="&IF($B$5="",2958465,$B$5),Consultas!$K$2:$K$1000,"Sí") -> 0 | H43: No aplica | I43: =IF(B43=0,"NO CALCULABLE",C43/B43) -> NO CALCULABLE | J43: =IF(C43=0,"NO CALCULABLE",E43/C43) -> NO CALCULABLE | K43: No aplica
A44: Otro | B44: =COUNTIFS(Consultas!$C$2:$C$1000,$A44,Consultas!$D$2:$D$1000,"<>",Consultas!$G$2:$G$1000,"<>Sí",Consultas!$B$2:$B$1000,">="&IF($B$4="",1,$B$4),Consultas!$B$2:$B$1000,"<="&IF($B$5="",2958465,$B$5)) -> 0 | C44: =COUNTIFS(Consultas!$C$2:$C$1000,$A44,Consultas!$D$2:$D$1000,"<>",Consultas!$G$2:$G$1000,"<>Sí",Consultas!$B$2:$B$1000,">="&IF($B$4="",1,$B$4),Consultas!$B$2:$B$1000,"<="&IF($B$5="",2958465,$B$5),Consultas!$H$2:$H$1000,"Sí") -> 0 | D44: =COUNTIFS(Consultas!$C$2:$C$1000,$A44,Consultas!$D$2:$D$1000,"<>",Consultas!$G$2:$G$1000,"<>Sí",Consultas!$B$2:$B$1000,">="&IF($B$4="",1,$B$4),Consultas!$B$2:$B$1000,"<="&IF($B$5="",2958465,$B$5),Consultas!$I$2:$I$1000,"Sí") -> 0 | E44: =COUNTIFS(Consultas!$C$2:$C$1000,$A44,Consultas!$D$2:$D$1000,"<>",Consultas!$G$2:$G$1000,"<>Sí",Consultas!$B$2:$B$1000,">="&IF($B$4="",1,$B$4),Consultas!$B$2:$B$1000,"<="&IF($B$5="",2958465,$B$5),Consultas!$J$2:$J$1000,"Sí") -> 0 | F44: =COUNTIFS(Consultas!$C$2:$C$1000,$A44,Consultas!$D$2:$D$1000,"<>",Consultas!$G$2:$G$1000,"<>Sí",Consultas!$B$2:$B$1000,">="&IF($B$4="",1,$B$4),Consultas!$B$2:$B$1000,"<="&IF($B$5="",2958465,$B$5),Consultas!$K$2:$K$1000,"Sí") -> 0 | G44: =SUMIFS(Consultas!$L$2:$L$1000,Consultas!$C$2:$C$1000,$A44,Consultas!$D$2:$D$1000,"<>",Consultas!$G$2:$G$1000,"<>Sí",Consultas!$B$2:$B$1000,">="&IF($B$4="",1,$B$4),Consultas!$B$2:$B$1000,"<="&IF($B$5="",2958465,$B$5),Consultas!$K$2:$K$1000,"Sí") -> 0 | H44: No aplica | I44: =IF(B44=0,"NO CALCULABLE",C44/B44) -> NO CALCULABLE | J44: =IF(C44=0,"NO CALCULABLE",E44/C44) -> NO CALCULABLE | K44: No aplica
...
